Workbook
Name avg_equity: Ratios!$C$33
Name avg_total_assets: Ratios!$C$34
Name avg_total_capitalization: Ratios!$C$35
Name BAL_receivables_YEAR: 'Balance Sheet'!$C$6
Name cost_capital: Ratios!$C$7
Name currentYear_after_tax_operating_income: Ratios!$C$19
Name currentYear_assets_current: Ratios!$C$23
Name currentYear_assets_total: Ratios!$C$28
Name currentYear_cash_marketable_securities: Ratios!$C$22
Name currentYear_cost_goods_sold_daily: Ratios!$C$25
Name currentYear_daily_sales_average: Ratios!$C$20
Name currentYear_debt_long_term: Ratios!$C$26
Name currentYear_equity: Ratios!$C$21
Name currentYear_liabilities_current: Ratios!$C$24
Name currentYear_liabilities_total: Ratios!$C$30
Name currentYear_total_capitalization: Ratios!$C$29
Name currentYear_working_capital_net: Ratios!$C$27
Name debt_long_term_equity: Ratios!$C$36
Name INC_cost_goods_sold: 'Income Statement'!$C$5
Name INC_depreciation: 'Income Statement'!$C$7
Name INC_ebit: 'Income Statement'!$C$8
Name INC_interest_expense: 'Income Statement'!$C$11
Name INC_net: 'Income Statement'!$C$15
Name INC_sales: 'Income Statement'!$C$4
Name market_capitalization: Ratios!$C$9
Name RATIO_asset_turnover: Ratios!$C$54
Name RATIO_debt_burden: Ratios!$C$68
Name RATIO_leverage: Ratios!$C$69
Name RATIO_operating_profit_margin: Ratios!$C$60
Name share_price: Ratios!$C$5
Name shares_outstanding: Ratios!$C$6
Name startYear_equity: Ratios!$C$12
Name startYear_inventory: Ratios!$C$13
Name startYear_receivables: Ratios!$C$14
Name startYear_total_assets: Ratios!$C$15
Name startYear_total_capitalization: Ratios!$C$16
Name tax_rate: Ratios!$C$8
Name yearCurrent: Ratios!$C$3
Name yearStart: Ratios!$C$4

Sheet Balance Sheet
B1: Balance Sheet — Microsoft Corporation (MSFT)
B2: ASSETS | C2: FY2024 (Jun 30, 2024) | D2: FY2023 (Jun 30, 2023) | F2: LIABILITIES & EQUITY | G2: FY2024 (Jun 30, 2024) | H2: FY2023 (Jun 30, 2023)
B3: (All figures in $millions) | F3: (All figures in $millions)
B4: Current Assets | F4: Current Liabilities
B5: Cash and marketable securities | C5: 18314 | D5: 34704 | F5: Debt due for repayment | G5: 9439 | H5: 9023
B6: Receivables | C6: 43482 | D6: 48688 | F6: Accounts payable | G6: 23572 | H6: 21113
B7: Inventories | C7: 2579 | D7: 2500 | F7: Other current liabilities | G7: 49577 | H7: 47516
B8: Other current assets | C8: 24285 | D8: 21260 | F8: Total current liabilities | G8: =SUM(G5:G7) -> 82588 | H8: =SUM(H5:H7) -> 77652
B9: Total current assets | C9: =SUM(C5:C8) -> 88660 | D9: =SUM(D5:D8) -> 107152
F10: Long-term debt | G10: 42688 | H10: 41990
B11: Fixed Assets | F11: Other long-term liabilities | G11: 27072 | H11: 25882
B12: Property, plant, and equipment | C12: 164278 | D12: 131460
B13: Less accumulated depreciation | C13: 68250 | D13: 59660 | F13: Total Liabilities | G13: =G8+G10+G11 -> 152348 | H13: =H8+H10+H11 -> 145524
B14: Net tangible fixed assets | C14: =C12-C13 -> 96028 | D14: =D12-D13 -> 71800
F15: Shareholders' Equity
B16: Other Assets | F16: Common stock and paid-in capital | G16: 97559 | H16: 86939
B17: Intangible assets (goodwill) | C17: 119021 | D17: 67524 | F17: Retained earnings | G17: 257689 | H17: 225533
B18: Other assets | C18: =G20-C9-C14-C17 -> 203887 | D18: =H20-D9-D14-D17 -> 211520 | F18: Total shareholders' equity | G18: =G16+G17 -> 355248 | H18: =H16+H17 -> 312472
B20: Total Assets | C20: =C9+C14+C17+C18 -> 507596 | D20: =D9+D14+D17+D18 -> 457996 | F20: Total Liabilities + Equity | G20: =G13+G18 -> 507596 | H20: =H13+H18 -> 457996
B21: Balance Check (TA − TL&E) | C21: =C20-G20 -> 0
B22: Source: Microsoft 10-K FY2024, SEC EDGAR

Sheet Income Statement
B1: Income Statement — Microsoft Corporation (MSFT)
B2: Line Item | C2: FY2024 (Jun 30, 2024) | D2: % of Sales
B3: (All figures in $millions)
B4: Net sales | C4: 245122 | D4: =IF(C$4=0,0,C4/C$4) -> 1
B5: less Cost of goods sold | C5: 74114 | D5: =IF(C$4=0,0,C5/C$4) -> 0.30235556
B6: less Selling, general & administrative | C6: 43930 | D6: =IF(C$4=0,0,C6/C$4) -> 0.17921688
B7: less Depreciation | C7: 17645 | D7: =IF(C$4=0,0,C7/C$4) -> 0.071984563
B8: Earnings before interest & taxes (EBIT) | C8: =C4-C5-C6-C7 -> 109433 | D8: =IF(C$4=0,0,C8/C$4) -> 0.446443
D9: =IF(C$4=0,0,C9/C$4) -> 0
B10: plus Other income | C10: 3269 | D10: =IF(C$4=0,0,C10/C$4) -> 0.013336216
B11: less Interest expense | C11: 2935 | D11: =IF(C$4=0,0,C11/C$4) -> 0.011973629
B12: Taxable income | C12: =C8+C10-C11 -> 109767 | D12: =IF(C$4=0,0,C12/C$4) -> 0.44780558
D13: =IF(C$4=0,0,C13/C$4) -> 0
B14: less Taxes | C14: 21631 | D14: =IF(C$4=0,0,C14/C$4) -> 0.088245853
B15: Net income | C15: =C12-C14 -> 88136 | D15: =IF(C$4=0,0,C15/C$4) -> 0.35955973
D16: =IF(C$4=0,0,C16/C$4) -> 0
B17: Allocation of Net Income | C17: =C15-C16 -> 88136 | D17: =IF(C$4=0,0,C17/C$4) -> 0.35955973
B18: Dividends | C18: 21771 | D18: =IF(C$4=0,0,C18/C$4) -> 0.088816997
B19: Addition to retained earnings | C19: =C15-C18 -> 66365 | D19: =IF(C$4=0,0,C19/C$4) -> 0.27074273
B21: Source: Microsoft 10-K FY2024, SEC EDGAR

Sheet Cash Flow Statement
B1: Cash Flow Statement — Microsoft Corporation (MSFT)
B2: Line Item | C2: FY2024 (Jun 30, 2024) | D2: Source / Notes
B3: (All figures in $millions)
B4: Operations:
B5: Net income | C5: ='Income Statement'!C15 -> 88136 | D5: [Income Statement]
B6: plus Depreciation | C6: ='Income Statement'!C7 -> 17645 | D6: [Income Statement]
B7: plus Changes in working capital items
B8: Decrease (increase) in accounts receivable | C8: 5193 | D8: [Balance Sheet]
B9: Decrease (increase) in inventories | C9: -79 | D9: [Balance Sheet]
B10: Decrease (increase) in other current assets | C10: -3025 | D10: [Balance Sheet]
B11: Increase (decrease) in accounts payable | C11: 2459 | D11: [Balance Sheet]
B12: Increase (decrease) in other current liabilities | C12: 2961 | D12: [Balance Sheet]
B13: Total change in working capital | C13: =SUM(C8:C12) -> 7509
B14: Cash provided by operations | C14: =C5+C6+C13 -> 113290
B16: Investments:
B17: Capital expenditures | C17: -44482
B18: plus Sales (acquisitions) of long-term assets | C18: 1532
B19: plus Other investing activities | C19: -12659
B20: Cash provided by (used for) investments | C20: =SUM(C17:C19) -> -55609
B22: Financing activities:
B23: Increase (decrease) in short-term debt | C23: -2801
B24: plus Increase (decrease) in long-term debt | C24: -2250
B25: plus Dividends | C25: =-'Income Statement'!C18 -> -21771
B26: plus Issues (repurchases) of stock | C26: -16870
B27: plus Other | C27: -672
B28: Cash provided by (used for) financing | C28: =SUM(C23:C27) -> -44364
B30: Net increase (decrease) in cash | C30: =C14+C20+C28 -> 13317
B32: Source: Microsoft 10-K FY2024, SEC EDGAR

Sheet Ratios
B1: Ratios — Microsoft Corporation (MSFT)
B2: Metric | C2: Input | D2: Named Range Formula | E2: Named Range
B3: Current year | C3: 2024 | E3: yearCurrent
B4: Start of year | C4: 2023 | D4: yearCurrent - 1 | E4: yearStart
B5: Share price | C5: 446.36 | E5: share_price
B6: Shares outstanding (M) | C6: 7433 | E6: shares_outstanding
B7: Cost of capital | C7: 0.088 | E7: cost_capital
B8: Tax rate | C8: ='Income Statement'!C14/'Income Statement'!C12 -> 0.19706287 | E8: tax_rate
B9: Market capitalization | C9: =C5*C6 -> 3317793.9 | D9: share_price × shares_outstanding | E9: market_capitalization
B11: ─── Start of Year (Prior Year Balance Sheet) ───
B12: Equity (start of year) | C12: ='Balance Sheet'!H18 -> 312472 | D12: BAL_equity_shareholders_2023 | E12: startYear_equity
B13: Inventories (start of year) | C13: ='Balance Sheet'!D7 -> 2500 | D13: BAL_inventories_2023 | E13: startYear_inventory
B14: Receivables (start of year) | C14: ='Balance Sheet'!D6 -> 48688 | D14: BAL_receivables_2023 | E14: startYear_receivables
B15: Total assets (start of year) | C15: ='Balance Sheet'!D20 -> 457996 | D15: BAL_assets_total_2023 | E15: startYear_total_assets
B16: Total capitalization (start of year) | C16: ='Balance Sheet'!H10+'Balance Sheet'!H18 -> 354462 | D16: BAL_debt_long_term_2023 + BAL_equity_shareholders_2023 | E16: startYear_total_capitalization
B18: ─── Current Year (Derived) ───
B19: After-tax operating income | C19: ='Income Statement'!C15+(1-C8)*'Income Statement'!C11 -> 90492.62 | D19: INC_net + (1−tax_rate) × INC_interest_expense | E19: currentYear_after_tax_operating_income
B20: Average daily sales | C20: ='Income Statement'!C4/365 -> 671.56712 | D20: INC_sales / 365 | E20: currentYear_daily_sales_average
B21: Book value of equity | C21: ='Balance Sheet'!G18 -> 355248 | D21: BAL_equity_shareholders_2024 | E21: currentYear_equity
B22: Cash + Mktable securities | C22: ='Balance Sheet'!C5 -> 18314 | D22: BAL_cash_marketable_securities_2024 | E22: currentYear_cash_marketable_securities
B23: Current assets | C23: ='Balance Sheet'!C9 -> 88660 | D23: BAL_assets_current_2024 | E23: currentYear_assets_current
B24: Current liabilities | C24: ='Balance Sheet'!G8 -> 82588 | D24: BAL_liabilities_current_2024 | E24: currentYear_liabilities_current
B25: Daily COGS | C25: ='Income Statement'!C5/365 -> 203.05205 | D25: INC_cost_goods_sold / 365 | E25: currentYear_cost_goods_sold_daily
B26: Long-term debt | C26: ='Balance Sheet'!G10 -> 42688 | D26: BAL_debt_long_term_2024 | E26: currentYear_debt_long_term
B27: Net working capital | C27: ='Balance Sheet'!C9-'Balance Sheet'!G8 -> 6072 | D27: BAL_assets_current_2024 − BAL_liabilities_current_2024 | E27: currentYear_working_capital_net
B28: Total assets | C28: ='Balance Sheet'!C20 -> 507596 | D28: BAL_assets_total_2024 | E28: currentYear_assets_total
B29: Total capitalization | C29: ='Balance Sheet'!G10+'Balance Sheet'!G18 -> 397936 | D29: BAL_debt_long_term_2024 + BAL_equity_shareholders_2024 | E29: currentYear_total_capitalization
B30: Total liabilities | C30: ='Balance Sheet'!G13 -> 152348 | D30: BAL_liabilities_total_2024 | E30: currentYear_liabilities_total
B32: ─── Mixed Year (Averages) ───
B33: Average equity | C33: =AVERAGE(C12,C21) -> 333860 | D33: AVERAGE(startYear_equity, currentYear_equity) | E33: avg_equity
B34: Average total assets | C34: =AVERAGE(C15,C28) -> 482796 | D34: AVERAGE(startYear_total_assets, currentYear_assets_total) | E34: avg_total_assets
B35: Average total capitalization | C35: =AVERAGE(C16,C29) -> 376199 | D35: AVERAGE(startYear_total_capitalization, currentYear_total_capitalization) | E35: avg_total_capitalization
B36: Long-term debt + Equity | C36: =C26+C21 -> 397936 | D36: currentYear_debt_long_term + currentYear_equity | E36: debt_long_term_equity
B39: Ratio | C39: Output ← Students Complete | D39: Named Range Formula (reference) | E39: Named Range
B40: Performance
B41: Market value added (MVA) | C41: =C9-C21 -> 2962545.9 | D41: market_capitalization − currentYear_equity | E41: RATIO_mva
B42: Market-to-book ratio | C42: =C9/C21 -> 9.3393738 | D42: market_capitalization / currentYear_equity | E42: RATIO_market_to_book
B43: Economic value added (EVA) | C43: =C19-(C7*C16) -> 59299.964 | D43: currentYear_after_tax_operating_income − (cost_capital × startYear_total_capitalization) | E43: RATIO_eva
B45: Profitability
B46: Return on assets (ROA) | C46: =C19/C15 -> 0.19758387 | D46: currentYear_after_tax_operating_income / startYear_total_assets | E46: RATIO_roa_start
...

Sheet Notes
B1: Notes & Assumptions — Microsoft Corporation (MSFT)
B3: Company: | C3: Microsoft Corporation
B4: Ticker: | C4: MSFT
B5: Industry: | C5: Technology – Cloud, Software & Productivity
B6: Fiscal Year (current): | C6: FY2024 (Jun 30, 2024)
B7: Fiscal Year (prior): | C7: FY2023 (Jun 30, 2023)
B8: Data Source: | C8: Microsoft 10-K FY2024, SEC EDGAR
B9: Units: | C9: All figures in millions of US dollars unless otherwise noted.
B10: Tax Rate: | C10: 16.1% — use as analyst assumption (adjust to effective rate if preferred)
B11: Cost of Capital: | C11: 8.8% — estimated WACC; students may refine using CAPM + class methodology
B12: Share Price: | C12: $446.36 — end-of-fiscal-year closing price
B13: Shares Outstanding: | C13: 7,433M shares
B15: BUS-314 Project Use: | C15: This workbook provides real financial statement data for the Accounting & Performance Ratios project.
... B20: AI Usage: | C20: [Document any AI tools used and how they were applied — required per course AI guidelines]
